#VRML_SIM R2022b utf8

EXTERNPROTO "../Components/SRCamera.proto"

PROTO Robot_2024 [
  field SFVec3f translation 0 0 0
  field SFRotation rotation 0 1 0 0
  field SFString controller ""
  field SFString model ""
  field SFString customData ""
  field SFColor flagColour 1 1 1
  field MFString controllerArgs []
]
{
  Robot {
    selfCollision FALSE
    translation IS translation
    rotation IS rotation
    controllerArgs IS controllerArgs
    children [
      DEF DRIVE_WHEELS Transform {
        translation 0.07 0 0.05
        children [
          DEF LEFT_WHEEL_CLUSTER Transform {
            translation 0 -0.101 0
            children [
              DEF LEFT_WHEEL_MOUNT Solid {
                translation 0 0.04 0
                rotation -1 0 0 1.5708
                name "left wheel mount"
                children [
                  DEF MOTOR_HOUSING Shape {
                    appearance PBRAppearance {
                      baseColor 0.36 0.36 0.36
                      roughness 0.3
                      metalness 0
                    }
                    geometry Cylinder {
                      height 0.07
                      radius 0.015
                      subdivision 12
                    }
                  }
                ]
                boundingObject DEF MOTOR_HOUSING_GEO Box {
                  size 0.03 0.03 0.07
                }
                physics Physics {
                  density 8000  # steel
                }
              }
              DEF LEFT_WHEEL HingeJoint {
                jointParameters HingeJointParameters {
                  position 0
                  axis 0 -1 0
                }
                device [
                  RotationalMotor {
                    name "left wheel"
                    maxVelocity 25
                    sound ""
                  }
                  PositionSensor {
                    name "left wheel sensor"
                  }
                ]
                endPoint Solid {
                  translation 0 0 0
                  rotation -1 0 0 1.5708
                  children [
                    DEF WHEEL_GEO Shape {
                      appearance PBRAppearance {
                        baseColor 0 0.0051864 0
                        roughness 0.3
                        metalness 0
                      }
                      geometry Cylinder {
                        height 0.021
                        radius 0.05
                        subdivision 32
                      }
                    }
                  ]
                  name "left wheel"
                  boundingObject USE WHEEL_GEO
                  physics Physics {
                    # density 20000
                  }
                }
              }
            ]
          }
          DEF RIGHT_WHEEL_CLUSTER Transform {
            translation 0 0.101 0
            children [
              DEF RIGHT_WHEEL_MOUNT Solid {
                translation 0 -0.04 0
                rotation -1 0 0 1.5708
                name "right wheel mount"
                children [
                  USE MOTOR_HOUSING
                ]
                boundingObject USE MOTOR_HOUSING_GEO
                physics Physics {
                  density 8000  # steel
                }
              }
              DEF RIGHT_WHEEL HingeJoint {
                jointParameters HingeJointParameters {
                  position 0
                  axis 0 -1 0
                }
                device [
                  RotationalMotor {
                    name "right wheel"
                    maxVelocity 25
                    sound ""
                  }
                  PositionSensor {
                    name "right wheel sensor"
                  }
                ]
                endPoint Solid {
                  translation 0 0 0
                  rotation -1 0 0 1.5708
                  children [
                    USE WHEEL_GEO
                  ]
                  name "right wheel"
                  boundingObject  USE WHEEL_GEO
                  physics Physics {
                    # density 20000
                  }
                }
              }
            ]
          }
        ]
      }
      DEF BASE_BOARD Solid {
        name "base"
        children [
          DEF body_geo Group {
            children [
              DEF body_core Transform {
                translation 0.07 0 0.03
                children [
                  Shape {
                    appearance DEF BODY_COLOUR PBRAppearance {
                      baseColor IS flagColour
                      roughness 0.3
                      metalness 0
                    }
                    geometry Box {
                      size 0.11 0.17 0.012
                    }
                  }
                ]
              }
              DEF body_front_spar Transform {
                translation 0 0 0.046
                children [
                  Shape {
                    appearance USE BODY_COLOUR
                    geometry Box {
                      size 0.03 0.35 0.044
                    }
                  }
                ]
              }
              DEF body_rear_spar Transform {
                translation 0.135 0 0.03
                children [
                  Shape {
                    appearance USE BODY_COLOUR
                    geometry Box {
                      size 0.02 0.23 0.012
                    }
                  }
                ]
              }
              DEF body_left_arm Transform {
                translation -0.0305 -0.1875 0.046
                children [
                  Shape {
                    appearance USE BODY_COLOUR
                    geometry Box {
                      size 0.091 0.025 0.044
                    }
                  }
                ]
              }
              DEF body_right_arm Transform {
                translation -0.0305 0.1875 0.046
                children [
                  Shape {
                    appearance USE BODY_COLOUR
                    geometry Box {
                      size 0.091 0.025 0.044
                    }
                  }
                ]
              }
            ]
          }
        ]
      }
      DEF CASTERS Transform {
        translation -0.1 0 0.0025
        children [
          DEF LEFT_CASTER Transform {
            translation 0.035 0.187 0
            children [
              DEF front_left_caster Solid {
                translation 0 0 0
                name "front_left_caster"
                children [
                  DEF CASTER_BALL Shape {
                    appearance DEF BALL_APPEARANCE PBRAppearance {
                      baseColor 0 0.0051864 0
                      roughness 0.0
                      metalness 0
                    }
                    geometry Sphere {
                      radius 0.005
                      # subdivision 2
                    }
                  }
                ]
                boundingObject USE CASTER_BALL
                physics Physics {
                  density 8000  # steel
                }
                contactMaterial "caster"
              }
              DEF CASTER_TOP Transform {
                translation 0 0 0.01075
                children [
                  DEF CASTER_TOP_CYLINDER Shape {
                    appearance PBRAppearance {
                      baseColor 0 0.0051864 0
                      roughness 0.5
                      metalness 0
                    }
                    geometry Cylinder {
                      height 0.0215
                      radius 0.01
                      subdivision 12
                      top FALSE
                    }
                  }
                ]
              }
            ]
          }
          DEF RIGHT_CASTER Transform {
            translation 0.035 -0.187 0
            children [
              DEF FRONT_RIGHT_CASTER Solid {
                translation 0 0 0
                name "front_right_caster"
                children [
                  USE CASTER_BALL
                ]
                boundingObject USE CASTER_BALL
                physics Physics {
                  density 8000  # steel
                }
                contactMaterial "caster"
              }
              USE CASTER_TOP
            ]
          }
        ]
      }
      DEF LIFTER Transform {
        translation 0.025 0 0
        children [
          DEF TOWER Solid {
            translation 0 0 0.21125
            children [
              DEF TOWER_GROUP Group {
                children [
                  DEF tower_body Shape {
                    appearance DEF TOWER_COLOUR PBRAppearance {
                      baseColor 0.0705882 0.0705882 0.0705882
                      roughness 0.4
                      metalness 0
                    }
                    geometry DEF tower_geo Box {
                      size 0.01 0.055 0.35
                    }
                  }
                  DEF tower_top Transform {
                    translation -0.019 0 0.175
                    children [
                      Shape {
                        appearance USE TOWER_COLOUR
                        geometry DEF tower_top_geo Box {
                          size 0.05 0.055 0.01
                        }
                      }
                    ]
                  }
                  DEF LEFT_ROD Transform {
                    translation -0.025 -0.01375 0
                    children [
                      DEF SUPPORT_ROD Shape {
                        appearance PBRAppearance {
                          baseColor 0.92 0.92 0.92
                          roughness 0.3
                        }
                        geometry Cylinder {
                          radius 0.004
                          height 0.35
                          subdivision 12
                          top FALSE
                          bottom FALSE
                        }
                      }
                    ]
                  }
                  DEF RIGHT_ROD Transform {
                    translation -0.025 0.01375 0
                    children [
                      USE SUPPORT_ROD
                    ]
                  }
                ]
              }
            ]
            boundingObject USE TOWER_GROUP
            name "vertical tower"
            physics Physics {
            }
          }
          SliderJoint {
            jointParameters JointParameters {
              axis 0 0 1
              maxStop 0.27
              minStop -0.01
              position 0
              staticFriction 20
            }
            device [
              LinearMotor {
                name "lifter"
                minPosition -0.01
                maxPosition 0.27
                maxVelocity 0.1
                maxForce 40
                sound ""
              }
              PositionSensor {
                name "lifter sensor"
              }
            ]
            endPoint DEF GRABBER_ASSEMBLY Solid {
              translation -0.025 0 0.087
              children [
                DEF hgrabber Group {
                  children [
                    DEF hgrabber_main Transform {
                      translation 0 0 0
                      children [
                        Shape {
                          appearance DEF HGRABBER_COLOUR PBRAppearance {
                            baseColor 0.5 0.5 0.5
                            roughness 0.3
                            metalness 0
                          }
                          geometry Box {
                            size 0.03 0.4 0.02
                          }
                        }
                      ]
                    }
                    DEF hgrabber_left Transform {
                      translation -0.05 -0.1875 0
                      children [
                        Shape {
                          appearance USE HGRABBER_COLOUR
                          geometry DEF HGRABBER_ARM Box {
                            size 0.07 0.025 0.02
                          }
                        }
                      ]
                    }
                    DEF hgrabber_right Transform {
                      translation -0.05 0.1875 0
                      children [
                        Shape {
                          appearance USE HGRABBER_COLOUR
                          geometry USE HGRABBER_ARM
                        }
                      ]
                    }
                    Transform {
                      translation 0 -0.01375 0
                      children [
                        DEF H_SLIDE_BEARING Shape {
                          appearance PBRAppearance {
                            baseColor 0.6471 0.4863 0
                            emissiveColor 0.6471 0.4863 0
                            emissiveIntensity 0.4
                          }
                          geometry Cylinder {
                            height 0.024
                            radius 0.008
                            subdivision 16
                          }
                        }
                      ]
                    }
                    Transform {
                      translation 0 0.01375 0
                      children [
                        USE H_SLIDE_BEARING
                      ]
                    }
                    DEF ROD1 Transform {
                      translation -0.03 0 0
                      rotation -1 0 0 1.5708
                      children [
                        DEF SUPPORT_ROD Shape {
                          appearance PBRAppearance {
                            baseColor 0.92 0.92 0.92
                            roughness 0.3
                          }
                          geometry Cylinder {
                            radius 0.004
                            height 0.37
                            subdivision 12
                            top FALSE
                            bottom FALSE
                          }
                        }
                      ]
                    }
                    DEF ROD2 Transform {
                      translation -0.065 0 0
                      rotation -1 0 0 1.5708
                      children [
                        USE SUPPORT_ROD
                      ]
                    }
                  ]
                }
                DEF GRABBER_LEFT Transform {
                  translation -0.055 -0.165 0
                  children [
                    SliderJoint {
                      jointParameters JointParameters {
                        axis 0 1 0
                        maxStop 0.124
                        minStop -0.01
                        position 0
                        springConstant 200
                        dampingConstant 100
                        staticFriction 20
                      }
                      device [
                        LinearMotor {
                          name "left gripper"
                          minPosition -0.01
                          maxPosition 0.124
                          maxVelocity 0.2
                          maxForce 100
                          sound ""
                        }
                        PositionSensor {
                          name "left gripper sensor"
                        }
                      ]
                      endPoint Solid {
                        children [
                          DEF GRIPPER_ARM Transform {
                            translation 0 0 0
                            children [
                              DEF GRIPPER_GEOMETRY Group {
                                children [
                                  DEF long_bit Transform {
                                    translation -0.086 0 0
                                    children [
                                      Shape {
                                        appearance DEF GRABBER_COLOUR PBRAppearance {
                                          baseColor 0.25 0.35 0.235
                                          roughness 1
                                          metalness 0
                                        }
                                        geometry Box {
                                          size 0.25 0.012 0.05
                                        }
                                      }
                                    ]
                                  }
                                ]
                              }
                            ]
                          }
                          DEF SLIDE_BEARINGS Group {
                            children [
                              Transform {
                                translation 0.025 0 0
                                rotation -1 0 0 1.5708
                                children [
                                  DEF SLIDE_BEARING Shape {
                                    appearance PBRAppearance {
                                      baseColor 0.6471 0.4863 0
                                      emissiveColor 0.6471 0.4863 0
                                      emissiveIntensity 0.4
                                    }
                                    geometry Cylinder {
                                      height 0.016
                                      radius 0.008
                                      subdivision 16
                                    }
                                  }
                                ]
                              }
                              Transform {
                                translation -0.01 0 0
                                rotation -1 0 0 1.5708
                                children [
                                  USE SLIDE_BEARING
                                ]
                              }
                            ]
                          }
                        ]
                        name "Gripper slider 1"
                        boundingObject USE GRIPPER_GEOMETRY
                        physics Physics {
                          # wood = ~700, leave at default
                        }
                      }
                    }
                  ]
                }
                DEF GRABBER_RIGHT Transform {
                  translation -0.055 0.165 0
                  children [
                    SliderJoint {
                      jointParameters JointParameters {
                        axis 0 -1 0
                        maxStop 0.124
                        minStop -0.01
                        position 0
                        springConstant 200
                        dampingConstant 100
                        staticFriction 20
                      }
                      device [
                        LinearMotor {
                          name "right gripper"
                          minPosition -0.01
                          maxPosition 0.124
                          maxVelocity 0.2
                          maxForce 100
                          sound ""
                        }
                        PositionSensor {
                          name "right gripper sensor"
                        }
                      ]
                      endPoint Solid {
                        children [
                          USE GRIPPER_ARM
                          Transform {
                            rotation -1 0 0 3.14
                            children [
                              USE SLIDE_BEARINGS
                            ]
                          }
                        ]
                        name "Gripper slider 2"
                        boundingObject USE GRIPPER_GEOMETRY
                        physics Physics {
                          # wood = ~700, leave at default
                        }
                      }
                    }
                  ]
                }
              ]
              boundingObject USE hgrabber
              name "horizontal grabber"
              physics Physics {
                # wood = ~700, leave at default
              }
            }
          }
        ]
      }
      DEF flag_pole Solid {
        translation 0.04 0.06 0.125
        children [
          LED {
            translation 0.06 0 0.062
            children [
              Shape {
                appearance PBRAppearance {
                  metalness 0
                  occlusionMapStrength 130
                  emissiveIntensity 10
                  baseColor IS flagColour
                }
                geometry Box {
                  size 0.1 0.005 0.075
                }
              }
            ]
            name "flag"
            color [
              0.1 0.1 0.7
              1 0.5 0.9
              0.8 0.8 0.1
              0.1 0.7 0.1
            ]
          }
          Shape {
            appearance PBRAppearance {
              baseColor 0.0705882 0.0705882 0.0705882
              roughness 0.4
              metalness 0
            }
            geometry DEF flag_pole Cylinder {
              height 0.2
              radius 0.01
              subdivision 12
              bottom FALSE
            }
          }
        ]
        boundingObject Box {
          size 0.02 0.02 0.2
        }
        name "flag pole"
        physics Physics {
        }
      }
      DEF SENSORS Transform {
        translation 0 0 0
        children [
          SRCamera {
            name "camera"
            translation -0.035 0 0.385
            rotation -0.1746747 0 0.9921977 3.1415927
          }
          Compass {
            name "robot compass"
          }
          DEF DISTANCE_SENSORS Group {
            children [
              DEF front_left DistanceSensor {
                translation -0.077 -0.187 0.045
                type "sonar"
                numberOfRays 10
                aperture 0.3
                rotation 0 0 1 3.1416
                children [
                  DEF GEO_DS Transform {
                    rotation 0 1 1 3.14159
                    children [
                      Shape {
                        appearance PBRAppearance {
                          baseColor 0.1 0.1 1
                          metalness 0
                        }
                        geometry Box {
                          size 0.002 0.045 0.02
                        }
                      }
                      Transform {
                        translation -0.007 0.013 0
                        rotation 0 -1 0 1.5708
                        children [
                          DEF SONAR_TX Shape {
                            appearance PBRAppearance {
                              baseColor 0.92 0.92 0.92
                              roughness 0.3
                            }
                            geometry Cylinder {
                              radius 0.008
                              height 0.012
                              subdivision 16
                              bottom FALSE
                            }
                          }
                        ]
                      }
                      Transform {
                        translation -0.007 -0.013 0
                        rotation 0 -1 0 1.5708
                        children [
                          USE SONAR_TX
                        ]
                      }
                    ]
                  }
                ]
                name "Front Left DS"
                lookupTable [
                  0 0 0
                  2 1000 0
                ]
              }
              DEF front_right DistanceSensor {
                translation -0.077 0.187 0.045
                type "sonar"
                numberOfRays 10
                aperture 0.3
                rotation 0 0 1 3.1416
                children [
                  USE GEO_DS
                ]
                name "Front Right DS"
                lookupTable [
                  0 0 0
                  2 1000 0
                ]
              }
              DEF left DistanceSensor {
                translation 0 -0.2 0.045
                type "sonar"
                numberOfRays 10
                aperture 0.3
                rotation 0 0 1 -1.5708
                children [
                  USE GEO_DS
                ]
                name "Left DS"
                lookupTable [
                  0 0 0
                  2 1000 0
                ]
              }
              DEF right DistanceSensor {
                translation 0 0.2 0.045
                type "sonar"
                numberOfRays 10
                aperture 0.3
                rotation 0 0 1 1.5708
                children [
                  USE GEO_DS
                ]
                name "Right DS"
                lookupTable [
                  0 0 0
                  2 1000 0
                ]
              }
              DEF front DistanceSensor {
                translation -0.016 0 0.045
                type "sonar"
                numberOfRays 10
                aperture 0.3
                rotation 0 0 1 3.1416
                children [
                  Transform {
                    rotation 1 0 0 1.5708
                    children [
                      USE GEO_DS
                    ]
                  }
                ]
                name "Front DS"
                lookupTable [
                  0 0 0
                  2 1000 0
                ]
              }
              DEF rear DistanceSensor {
                translation 0.14 0 0.046
                type "sonar"
                numberOfRays 10
                aperture 0.3
                rotation 0 1 0 -0.1
                children [
                  Transform {
                    rotation 1 0 0 1.5708
                    children [
                      USE GEO_DS
                    ]
                  }
                ]
                name "Back DS"
                lookupTable [
                  0 0 0
                  2 1000 0
                ]
              }
            ]
          }
          TouchSensor {
            translation 0.15 0 0.03
            rotation 0 0 1 3.14
            children [
              Shape {
                appearance PBRAppearance {
                  baseColor 0.5 0 0
                  roughness 0.7
                }
                geometry DEF BUMPER Box {
                  size 0.01 0.2 0.01
                }
              }
            ]
            name "back bump sensor"
            boundingObject Box {
              size 0.03 0.2 0.01
            }
          }
          LED {
            translation 0.033 0 0.25
            rotation 0 1 0 1.5708
            children [
              Shape {
                appearance DEF APP_LED PBRAppearance {
                  baseColor 0.6 0.4 0.4
                  metalness 0
                  emissiveIntensity 100
                }
                geometry Capsule {
                  height 0.005
                  radius 0.01
                }
              }
            ]
            name "led 1"
            color [
              1 0 0
            ]
          }
          LED {
            translation 0.033 0 0.35
            rotation 0 1 0 1.5708
            children [
              Shape {
                appearance DEF APP_LED PBRAppearance {
                  baseColor 0.4 0.6 0.4
                  metalness 0
                  emissiveIntensity 100
                }
                geometry Capsule {
                  height 0.005
                  radius 0.01
                }
              }
            ]
            name "led 2"
            color [
              0 1 0
            ]
          }
        ]
      }
    ]
    name IS model
    model IS model
    boundingObject USE body_geo
    physics Physics {
      # wood = ~700, leave at default
    }
    controller IS controller
    customData IS customData
  }
}
