#VRML_SIM R2020a utf8
WorldInfo {
}
Viewpoint {
  orientation 0.03852089197998513 -0.9536757725383965 -0.29835995333549536 3.450882755330571
  position 3.049519814840676 3.7821899170413933 -6.466006674826357

}
TexturedBackgroundLight {
  texture "noon_park_empty"
}
TexturedBackground {
}
DEF FLOOR Solid {
  children [
    DEF FLOOR_SHAPE Shape {
      appearance DEF APP_FLOOR PBRAppearance {
        baseColor 0.5 0.5 0.5
        baseColorMap ImageTexture {
          url [
            "A:/antoi/Documents/GitHub/competition-simulator/textures/empty-arena.png"
          ]
        }
        roughness 1
        metalness 0
      }
      geometry Plane {
        size 5.75 5.75
      }
    }
  ]
  name "ground"
  boundingObject USE FLOOR_SHAPE
  locked TRUE
}
DEF WALL Solid {
  children [
    Shape {
      appearance DEF WALL_APPEARANCE PBRAppearance {
        baseColor 0.2 0.2 0.2
        roughness 1
        metalness 0
      }
      geometry DEF WALL_GEOMETRY IndexedFaceSet {
        coord Coordinate {
          point [
            2.975 0 2.975
            2.975 0 -2.975
            -2.975 0 -2.975
            -2.975 0 2.975
            -2.875 0 2.975
            -2.875 0 -2.875
            2.875 0 -2.875
            2.875 0 2.875
            -2.875 0 2.875
            -2.875 0 2.875
            2.875 0 2.875
            2.975 0.1 2.975
            2.975 0.1 -2.975
            -2.975 0.1 -2.975
            -2.975 0.1 2.975
            -2.875 0.1 2.975
            -2.875 0.1 -2.875
            2.875 0.1 -2.875
            2.875 0.1 2.875
            -2.875 0.1 2.875
            -2.875 0.1 2.975
            2.975 0.1 2.975
          ]
        }
        coordIndex [
          10, 9, 8, 7, 6, 5, 4, 3, 2, 1, 0, -1, 11, 12, 13, 14, 15, 16, 17, 18, 19, 20, 21, -1, 0, 1, 12, 11, -1, 1, 2, 13, 12, -1, 2, 3, 14, 13, -1, 3, 4, 15, 14, -1, 4, 5, 16, 15, -1, 5, 6, 17, 16, -1, 6, 7, 18, 17, -1, 7, 8, 19, 18, -1, 8, 9, 20, 19, -1, 9, 10, 21, 20, -1
        ]
      }
    }
  ]
  name "wall"
  boundingObject USE WALL_GEOMETRY
  locked TRUE
}
DEF STAGE Solid {
  translation 0 0.09 0
  children [
    Shape {
      appearance DEF APP_FLOOR PBRAppearance {
        baseColor 0.5 0.5 0.5
        baseColorMap ImageTexture {
          url [
            "A:/antoi/Documents/GitHub/competition-simulator/textures/stage.png"
          ]
          repeatS FALSE
          repeatT FALSE
        }
        roughness 1
        metalness 0
      }
      geometry DEF STAGE_GEOMETRY Box {
        size 1.2 0.18 1.2
      }
    }
  ]
  boundingObject USE STAGE_GEOMETRY
  locked TRUE
}
DEF TOKEN_GOLD Solid {
  translation 0.8799999990290108 0.12499607891462448 0.8999999990290108
  rotation 0.7071067801442413 1.7528871940598554e-09 -0.7071067822288535 -1.0987799130863795e-08
  children [
    Shape {
      appearance DEF TOKEN_APPEARANCE PBRAppearance {
        baseColor 1 1 0
        metalness 0
      }
      geometry DEF TOKEN_GEOMETRY Box {
        size 0.25 0.25 0.25
      }
    }
  ]
  name "solid(1)"
  boundingObject USE TOKEN_GEOMETRY
  physics Physics {
    density -1
    mass 0.01
  }
  recognitionColors [
    1 1 0
  ]
}
DEF TOKEN_GOLD Solid {
  translation -0.8800000009709892 0.1249960789146245 0.8999999990290108
  rotation -0.7071067824979693 4.0021568839374943e-10 0.7071067798751257 1.0987799115647408e-08
  children [
    Shape {
      appearance DEF TOKEN_APPEARANCE PBRAppearance {
        baseColor 1 1 0
        metalness 0
      }
      geometry DEF TOKEN_GEOMETRY Box {
        size 0.25 0.25 0.25
      }
    }
  ]
  name "solid(2)"
  boundingObject USE TOKEN_GEOMETRY
  physics Physics {
    density -1
    mass 0.01
  }
  recognitionColors [
    1 1 0
  ]
}
DEF TOKEN_GOLD Solid {
  translation -0.8800000009709894 0.12499607891462448 -0.9000000009709892
  rotation -0.7071067811575862 1.3842701422872506e-09 0.7071067812155089 1.0987799104884908e-08
  children [
    Shape {
      appearance DEF TOKEN_APPEARANCE PBRAppearance {
        baseColor 1 1 0
        metalness 0
      }
      geometry DEF TOKEN_GEOMETRY Box {
        size 0.25 0.25 0.25
      }
    }
  ]
  name "solid(3)"
  boundingObject USE TOKEN_GEOMETRY
  physics Physics {
    density -1
    mass 0.01
  }
  recognitionColors [
    1 1 0
  ]
}
DEF TOKEN_GOLD Solid {
  translation 0.8799999990290108 0.1249960789146245 -0.9000000009709892
  rotation -0.7071067801418399 3.8134708331229313e-10 0.7071067822312551 1.0987799112882934e-08
  children [
    Shape {
      appearance DEF TOKEN_APPEARANCE PBRAppearance {
        baseColor 1 1 0
        metalness 0
      }
      geometry DEF TOKEN_GEOMETRY Box {
        size 0.25 0.25 0.25
      }
    }
  ]
  name "solid(4)"
  boundingObject USE TOKEN_GEOMETRY
  physics Physics {
    density -1
    mass 0.01
  }
  recognitionColors [
    1 1 0
  ]
}
DEF TOKEN_GOLD Solid {
  translation -0.4 0.30499607988564803 3.0148555970783117e-18
  rotation 0.7337479633392148 0.053579500766779094 -0.6773058123131211 7.553320235066303e-17
  children [
    Shape {
      appearance DEF TOKEN_APPEARANCE PBRAppearance {
        baseColor 1 1 0
        metalness 0
      }
      geometry DEF TOKEN_GEOMETRY Box {
        size 0.25 0.25 0.25
      }
    }
  ]
  name "solid(5)"
  boundingObject USE TOKEN_GEOMETRY
  physics Physics {
    density -1
    mass 0.01
  }
  recognitionColors [
    1 1 0
  ]
}
DEF TOKEN_GOLD Solid {
  translation 3.9915151154245094e-18 0.30499607988564803 0.4
  rotation -0.9082282710147144 0.28890868939977055 0.3027427570049028 -1.408210870753068e-17
  children [
    Shape {
      appearance DEF TOKEN_APPEARANCE PBRAppearance {
        baseColor 1 1 0
        metalness 0
      }
      geometry DEF TOKEN_GEOMETRY Box {
        size 0.25 0.25 0.25
      }
    }
  ]
  name "solid(6)"
  boundingObject USE TOKEN_GEOMETRY
  physics Physics {
    density -1
    mass 0.01
  }
  recognitionColors [
    1 1 0
  ]
}
DEF TOKEN_GOLD Solid {
  translation 9.281045382352137e-18 0.304996079885648 -0.4
  rotation -0.9832539366285931 0.14586307974120555 0.10925043740317648 -3.9022785774554895e-17
  children [
    Shape {
      appearance DEF TOKEN_APPEARANCE PBRAppearance {
        baseColor 1 1 0
        metalness 0
      }
      geometry DEF TOKEN_GEOMETRY Box {
        size 0.25 0.25 0.25
      }
    }
  ]
  name "solid(7)"
  boundingObject USE TOKEN_GEOMETRY
  physics Physics {
    density -1
    mass 0.01
  }
  recognitionColors [
    1 1 0
  ]
}
DEF TOKEN_GOLD Solid {
  translation 0.4 0.30499607988564803 3.0148555970783117e-18
  rotation 0.7337479633392148 0.053579500766779094 -0.6773058123131211 7.553320235066303e-17
  children [
    Shape {
      appearance DEF TOKEN_APPEARANCE PBRAppearance {
        baseColor 1 1 0
        metalness 0
      }
      geometry DEF TOKEN_GEOMETRY Box {
        size 0.25 0.25 0.25
      }
    }
  ]
  name "solid(8)"
  boundingObject USE TOKEN_GEOMETRY
  physics Physics {
    density -1
    mass 0.01
  }
  recognitionColors [
    1 1 0
  ]
}
DEF TOKEN_SILVER Solid {
  translation 0.32 0.30499607988564803 0.32
  rotation 0.842227745448497 0.058274940778106285 0.5359631107399557 5.568068828603349e-17
  children [
    Shape {
      appearance DEF TOKEN_APPEARANCE PBRAppearance {
        metalness 0
      }
      geometry DEF TOKEN_GEOMETRY Box {
        size 0.25 0.25 0.25
      }
    }
  ]
  name "solid(9)"
  boundingObject USE TOKEN_GEOMETRY
  physics Physics {
    density -1
    mass 0.01
  }
  recognitionColors [
    1 1 1
  ]
}
DEF TOKEN_SILVER Solid {
  translation -0.32 0.30499607988564803 0.32
  rotation 0.974225554908581 0.018437987065253136 -0.2248212819019787 5.688860563146329e-17
  children [
    Shape {
      appearance DEF TOKEN_APPEARANCE PBRAppearance {
        metalness 0
      }
      geometry DEF TOKEN_GEOMETRY Box {
        size 0.25 0.25 0.25
      }
    }
  ]
  name "solid(10)"
  boundingObject USE TOKEN_GEOMETRY
  physics Physics {
    density -1
    mass 0.01
  }
  recognitionColors [
    1 1 1
  ]
}
DEF TOKEN_SILVER Solid {
  translation -0.32 0.30499607988564803 -0.32
  rotation 0.7337479633392148 0.053579500766779094 -0.6773058123131211 7.553320235066303e-17
  children [
    Shape {
      appearance DEF TOKEN_APPEARANCE PBRAppearance {
        metalness 0
      }
      geometry DEF TOKEN_GEOMETRY Box {
        size 0.25 0.25 0.25
      }
    }
  ]
  name "solid(11)"
  boundingObject USE TOKEN_GEOMETRY
  physics Physics {
    density -1
    mass 0.01
  }
  recognitionColors [
    1 1 1
  ]
}
DEF TOKEN_SILVER Solid {
  translation 0.32 0.30499607988564803 -0.32
  rotation 0.7337479633392148 0.053579500766779094 -0.6773058123131211 7.553320235066303e-17
  children [
    Shape {
      appearance DEF TOKEN_APPEARANCE PBRAppearance {
        metalness 0
      }
      geometry DEF TOKEN_GEOMETRY Box {
        size 0.25 0.25 0.25
      }
    }
  ]
  name "solid(12)"
  boundingObject USE TOKEN_GEOMETRY
  physics Physics {
    density -1
    mass 0.01
  }
  recognitionColors [
    1 1 1
  ]
}
DEF TOKEN_SILVER Solid {
  translation -1.3731863149147013e-09 0.1249960789146245 1.3000000000000023
  rotation -5.493879226546504e-09 1 1.3263426583374052e-08 0.7853996938995743
  children [
    Shape {
      appearance DEF TOKEN_APPEARANCE PBRAppearance {
        metalness 0
      }
      geometry DEF TOKEN_GEOMETRY Box {
        size 0.25 0.25 0.25
      }
    }
  ]
  name "solid(13)"
  boundingObject USE TOKEN_GEOMETRY
  physics Physics {
    density -1
    mass 0.01
  }
  recognitionColors [
    1 1 1
  ]
}
DEF TOKEN_SILVER Solid {
  translation -1.3731863149147013e-09 0.1249960789146245 -1.2999999999999978
  rotation -5.493879226546504e-09 1 1.3263426583374052e-08 0.7853996938995743
  children [
    Shape {
      appearance DEF TOKEN_APPEARANCE PBRAppearance {
        metalness 0
      }
      geometry DEF TOKEN_GEOMETRY Box {
        size 0.25 0.25 0.25
      }
    }
  ]
  name "solid(14)"
  boundingObject USE TOKEN_GEOMETRY
  physics Physics {
    density -1
    mass 0.01
  }
  recognitionColors [
    1 1 1
  ]
}
DEF TOKEN_SILVER Solid {
  translation 1.299999998626814 0.12499607891462448 2.106022558667375e-15
  rotation -5.493879200667026e-09 1 1.32634264690066e-08 0.7853996938995741
  children [
    Shape {
      appearance DEF TOKEN_APPEARANCE PBRAppearance {
        metalness 0
      }
      geometry DEF TOKEN_GEOMETRY Box {
        size 0.25 0.25 0.25
      }
    }
  ]
  name "solid(15)"
  boundingObject USE TOKEN_GEOMETRY
  physics Physics {
    density -1
    mass 0.01
  }
  recognitionColors [
    1 1 1
  ]
}
DEF TOKEN_SILVER Solid {
  translation -1.300000001373186 0.12499607891462448 2.106022558667375e-15
  rotation -5.493879200667026e-09 1 1.32634264690066e-08 0.7853996938995741
  children [
    Shape {
      appearance DEF TOKEN_APPEARANCE PBRAppearance {
        metalness 0
      }
      geometry DEF TOKEN_GEOMETRY Box {
        size 0.25 0.25 0.25
      }
    }
  ]
  name "solid(16)"
  boundingObject USE TOKEN_GEOMETRY
  physics Physics {
    density -1
    mass 0.01
  }
  recognitionColors [
    1 1 1
  ]
}
DEF Cristo Robot {
  translation 0.785539 0.0307792 -1.69614
  rotation -0.0011620910356194148 0.9999972788023701 0.002022852510641417 2.040255102294615
  children [
    Camera {
      translation 0 0.038 0.075
      rotation 0 1 0 3.14159
      children [
        Shape {
          appearance PBRAppearance {
            baseColor 0 0 0
            metalness 0
          }
          geometry Box {
            size 0.025 0.025 0.05
          }
        }
      ]
      width 800
      height 600
    }
    DEF WHEEL3 HingeJoint {
      jointParameters HingeJointParameters {
        position 0.0011182143343676546
        anchor 0 0 0.05
      }
      device [
        RotationalMotor {
          name "wheel3"
        }
      ]
      endPoint Solid {
        translation -1.103896341458872e-05 0.00017789140757968054 -0.10000016011171416
        rotation 0.0005599236167505286 -0.0005582898758087872 0.9999996873989302 1.5708001925439257
        children [
          Shape {
            appearance PBRAppearance {
              baseColor 0 0.4 0
              metalness 0
            }
            geometry DEF rearWheel_geometry Cylinder {
              height 0.05
              radius 0.04
            }
          }
        ]
        name "solid(2)"
        boundingObject USE rearWheel_geometry
        physics Physics {
        }
      }
    }
    DEF BODY Shape {
      appearance PBRAppearance {
        baseColor 0.917647 0.145098 0.145098
        roughness 1
        metalness 0
      }
      geometry Box {
        size 0.2 0.05 0.2
      }
    }
    DEF WHEEL1 HingeJoint {
      jointParameters HingeJointParameters {
        position 833.3289519336082
        anchor 0.06 0 0.05
      }
      device [
        RotationalMotor {
          name "wheel1"
        }
      ]
      endPoint Solid {
        translation 0.11000111835861384 8.157096417122021e-06 0.050006667284753226
        rotation 0.6886410201438272 -0.6886441659397087 -0.22703030214592948 3.5880813310074195
        children [
          DEF WHEEL Shape {
            appearance PBRAppearance {
              baseColor 0.305882 0.898039 0.25098
              roughness 1
              metalness 0
            }
            geometry Cylinder {
              height 0.02
              radius 0.04
              subdivision 24
            }
          }
        ]
        boundingObject USE WHEEL
        physics Physics {
        }
      }
    }
    DEF WHEEL2 HingeJoint {
      jointParameters HingeJointParameters {
        position 723.6331814542078
        anchor -0.06 0 0.05
      }
      device [
        RotationalMotor {
          name "wheel2"
        }
      ]
      endPoint Solid {
        translation -0.10999544794656736 6.517034217833518e-06 0.05000820414250385
        rotation -0.3977840423789284 0.3977837913842228 -0.8267623061924582 4.523285836448139
        children [
          USE WHEEL
        ]
        name "solid(1)"
        boundingObject USE WHEEL
        physics Physics {
        }
      }
    }
    DEF DS_RIGHT DistanceSensor {
      translation -0.08 0 0.1
      rotation 0 1 0 -1.87079
      children [
        Shape {
          appearance PBRAppearance {
            baseColor 0.184314 0.596078 0.847059
            roughness 1
            metalness 0
          }
          geometry Box {
            size 0.01 0.01 0.01
          }
        }
      ]
      name "ds_right"
      lookupTable [
        0 0 0
        0.5 1000 0
      ]
    }
    DEF DS_LEFT DistanceSensor {
      translation 0.08 0 0.1
      rotation 0 1 0 -1.27079
      children [
        Shape {
          appearance PBRAppearance {
            baseColor 0.184314 0.596078 0.847059
            roughness 1
            metalness 0
          }
          geometry Box {
            size 0.01 0.01 0.01
          }
        }
      ]
      name "ds_left"
      lookupTable [
        0 0 0
        0.5 1000 0
      ]
    }
  ]
  name "Cristo"
  boundingObject USE BODY
  physics Physics {
    density -1
    mass 1
  }
  controller "example_controller"
}
