#VRML_SIM R2020a utf8
WorldInfo {
}
Viewpoint {
  orientation 0.39659607717689693 0.9108331303223832 0.11443146540626609 5.5321775140095095
  position -7.540455791517064 4.226136221453764 8.411097068441851
}
TexturedBackgroundLight {
  texture "noon_park_empty"
}
TexturedBackground {
}
DEF FLOOR Solid {
  children [
    DEF FLOOR_SHAPE Shape {
      appearance DEF APP_FLOOR PBRAppearance {
        baseColor 0.5 0.5 0.5
        baseColorMap ImageTexture {
          url [
            "C:/Users/philr/Documents/Auxiliary Activities/11. Student Robotics/1. Webots/testProject/textures/arena.JPG"
          ]
        }
        roughness 1
        metalness 0
      }
      geometry Plane {
        size 5.75 5.75
      }
    }
  ]
  name "ground"
  boundingObject USE FLOOR_SHAPE
  locked TRUE
}
DEF WALL Solid {
  children [
    Shape {
      appearance DEF WALL_APPEARANCE PBRAppearance {
        baseColor 0.2 0.2 0.2
        roughness 1
        metalness 0
      }
      geometry DEF WALL_GEOMETRY IndexedFaceSet {
        coord Coordinate {
          point [
            2.975 0 2.975
            2.975 0 -2.975
            -2.975 0 -2.975
            -2.975 0 2.975
            -2.875 0 2.975
            -2.875 0 -2.875
            2.875 0 -2.875
            2.875 0 2.875
            -2.875 0 2.875
            -2.875 0 2.875
            2.875 0 2.875
            2.975 0.1 2.975
            2.975 0.1 -2.975
            -2.975 0.1 -2.975
            -2.975 0.1 2.975
            -2.875 0.1 2.975
            -2.875 0.1 -2.875
            2.875 0.1 -2.875
            2.875 0.1 2.875
            -2.875 0.1 2.875
            -2.875 0.1 2.975
            2.975 0.1 2.975
          ]
        }
        coordIndex [
          10, 9, 8, 7, 6, 5, 4, 3, 2, 1, 0, -1, 11, 12, 13, 14, 15, 16, 17, 18, 19, 20, 21, -1, 0, 1, 12, 11, -1, 1, 2, 13, 12, -1, 2, 3, 14, 13, -1, 3, 4, 15, 14, -1, 4, 5, 16, 15, -1, 5, 6, 17, 16, -1, 6, 7, 18, 17, -1, 7, 8, 19, 18, -1, 8, 9, 20, 19, -1, 9, 10, 21, 20, -1
        ]
      }
    }
  ]
  name "wall"
  boundingObject USE WALL_GEOMETRY
  locked TRUE
}
DEF STAGE Solid {
  translation 0 0.09 0
  children [
    Shape {
      appearance DEF APP_FLOOR PBRAppearance {
        baseColor 0.5 0.5 0.5
        baseColorMap ImageTexture {
          url [
            "C:/Users/philr/Documents/Auxiliary Activities/11. Student Robotics/1. Webots/testProject/textures/stage.JPG"
          ]
          repeatS FALSE
          repeatT FALSE
        }
        roughness 1
        metalness 0
      }
      geometry DEF STAGE_GEOMETRY Box {
        size 1.2 0.18 1.2
      }
    }
  ]
  boundingObject USE STAGE_GEOMETRY
  locked TRUE
}
DEF TOKEN_GOLD Solid {
  translation 0.8799999990290108 0.12499607891462448 0.8999999990290108
  rotation 0.7071067801442413 1.7528871940598554e-09 -0.7071067822288535 -1.0987799130863795e-08
  children [
    Shape {
      appearance DEF TOKEN_APPEARANCE PBRAppearance {
        baseColor 1 1 0
        metalness 0
      }
      geometry DEF TOKEN_GEOMETRY Box {
        size 0.25 0.25 0.25
      }
    }
  ]
  name "solid(1)"
  boundingObject USE TOKEN_GEOMETRY
  physics Physics {
    density -1
    mass 0.01
  }
  recognitionColors [
    1 1 0
  ]
}
DEF TOKEN_GOLD Solid {
  translation -0.8800000009709892 0.1249960789146245 0.8999999990290108
  rotation -0.7071067824979693 4.0021568839374943e-10 0.7071067798751257 1.0987799115647408e-08
  children [
    Shape {
      appearance DEF TOKEN_APPEARANCE PBRAppearance {
        baseColor 1 1 0
        metalness 0
      }
      geometry DEF TOKEN_GEOMETRY Box {
        size 0.25 0.25 0.25
      }
    }
  ]
  name "solid(2)"
  boundingObject USE TOKEN_GEOMETRY
  physics Physics {
    density -1
    mass 0.01
  }
  recognitionColors [
    1 1 0
  ]
}
DEF TOKEN_GOLD Solid {
  translation -0.8800000009709894 0.12499607891462448 -0.9000000009709892
  rotation -0.7071067811575862 1.3842701422872506e-09 0.7071067812155089 1.0987799104884908e-08
  children [
    Shape {
      appearance DEF TOKEN_APPEARANCE PBRAppearance {
        baseColor 1 1 0
        metalness 0
      }
      geometry DEF TOKEN_GEOMETRY Box {
        size 0.25 0.25 0.25
      }
    }
  ]
  name "solid(3)"
  boundingObject USE TOKEN_GEOMETRY
  physics Physics {
    density -1
    mass 0.01
  }
  recognitionColors [
    1 1 0
  ]
}
DEF TOKEN_GOLD Solid {
  translation 0.8799999990290108 0.1249960789146245 -0.9000000009709892
  rotation -0.7071067801418399 3.8134708331229313e-10 0.7071067822312551 1.0987799112882934e-08
  children [
    Shape {
      appearance DEF TOKEN_APPEARANCE PBRAppearance {
        baseColor 1 1 0
        metalness 0
      }
      geometry DEF TOKEN_GEOMETRY Box {
        size 0.25 0.25 0.25
      }
    }
  ]
  name "solid(4)"
  boundingObject USE TOKEN_GEOMETRY
  physics Physics {
    density -1
    mass 0.01
  }
  recognitionColors [
    1 1 0
  ]
}
DEF TOKEN_GOLD Solid {
  translation -0.4 0.30499607988564803 3.0148555970783117e-18
  rotation 0.7337479633392148 0.053579500766779094 -0.6773058123131211 7.553320235066303e-17
  children [
    Shape {
      appearance DEF TOKEN_APPEARANCE PBRAppearance {
        baseColor 1 1 0
        metalness 0
      }
      geometry DEF TOKEN_GEOMETRY Box {
        size 0.25 0.25 0.25
      }
    }
  ]
  name "solid(5)"
  boundingObject USE TOKEN_GEOMETRY
  physics Physics {
    density -1
    mass 0.01
  }
  recognitionColors [
    1 1 0
  ]
}
DEF TOKEN_GOLD Solid {
  translation 3.9915151154245094e-18 0.30499607988564803 0.4
  rotation -0.9082282710147144 0.28890868939977055 0.3027427570049028 -1.408210870753068e-17
  children [
    Shape {
      appearance DEF TOKEN_APPEARANCE PBRAppearance {
        baseColor 1 1 0
        metalness 0
      }
      geometry DEF TOKEN_GEOMETRY Box {
        size 0.25 0.25 0.25
      }
    }
  ]
  name "solid(6)"
  boundingObject USE TOKEN_GEOMETRY
  physics Physics {
    density -1
    mass 0.01
  }
  recognitionColors [
    1 1 0
  ]
}
DEF TOKEN_GOLD Solid {
  translation 9.281045382352137e-18 0.304996079885648 -0.4
  rotation -0.9832539366285931 0.14586307974120555 0.10925043740317648 -3.9022785774554895e-17
  children [
    Shape {
      appearance DEF TOKEN_APPEARANCE PBRAppearance {
        baseColor 1 1 0
        metalness 0
      }
      geometry DEF TOKEN_GEOMETRY Box {
        size 0.25 0.25 0.25
      }
    }
  ]
  name "solid(7)"
  boundingObject USE TOKEN_GEOMETRY
  physics Physics {
    density -1
    mass 0.01
  }
  recognitionColors [
    1 1 0
  ]
}
DEF TOKEN_GOLD Solid {
  translation 0.4 0.30499607988564803 3.0148555970783117e-18
  rotation 0.7337479633392148 0.053579500766779094 -0.6773058123131211 7.553320235066303e-17
  children [
    Shape {
      appearance DEF TOKEN_APPEARANCE PBRAppearance {
        baseColor 1 1 0
        metalness 0
      }
      geometry DEF TOKEN_GEOMETRY Box {
        size 0.25 0.25 0.25
      }
    }
  ]
  name "solid(8)"
  boundingObject USE TOKEN_GEOMETRY
  physics Physics {
    density -1
    mass 0.01
  }
  recognitionColors [
    1 1 0
  ]
}
DEF TOKEN_SILVER Solid {
  translation 0.32 0.30499607988564803 0.32
  rotation 0.842227745448497 0.058274940778106285 0.5359631107399557 5.568068828603349e-17
  children [
    Shape {
      appearance DEF TOKEN_APPEARANCE PBRAppearance {
        metalness 0
      }
      geometry DEF TOKEN_GEOMETRY Box {
        size 0.25 0.25 0.25
      }
    }
  ]
  name "solid(9)"
  boundingObject USE TOKEN_GEOMETRY
  physics Physics {
    density -1
    mass 0.01
  }
  recognitionColors [
    1 1 1
  ]
}
DEF TOKEN_SILVER Solid {
  translation -0.32 0.30499607988564803 0.32
  rotation 0.974225554908581 0.018437987065253136 -0.2248212819019787 5.688860563146329e-17
  children [
    Shape {
      appearance DEF TOKEN_APPEARANCE PBRAppearance {
        metalness 0
      }
      geometry DEF TOKEN_GEOMETRY Box {
        size 0.25 0.25 0.25
      }
    }
  ]
  name "solid(10)"
  boundingObject USE TOKEN_GEOMETRY
  physics Physics {
    density -1
    mass 0.01
  }
  recognitionColors [
    1 1 1
  ]
}
DEF TOKEN_SILVER Solid {
  translation -0.32 0.30499607988564803 -0.32
  rotation 0.7337479633392148 0.053579500766779094 -0.6773058123131211 7.553320235066303e-17
  children [
    Shape {
      appearance DEF TOKEN_APPEARANCE PBRAppearance {
        metalness 0
      }
      geometry DEF TOKEN_GEOMETRY Box {
        size 0.25 0.25 0.25
      }
    }
  ]
  name "solid(11)"
  boundingObject USE TOKEN_GEOMETRY
  physics Physics {
    density -1
    mass 0.01
  }
  recognitionColors [
    1 1 1
  ]
}
DEF TOKEN_SILVER Solid {
  translation 0.32 0.30499607988564803 -0.32
  rotation 0.7337479633392148 0.053579500766779094 -0.6773058123131211 7.553320235066303e-17
  children [
    Shape {
      appearance DEF TOKEN_APPEARANCE PBRAppearance {
        metalness 0
      }
      geometry DEF TOKEN_GEOMETRY Box {
        size 0.25 0.25 0.25
      }
    }
  ]
  name "solid(12)"
  boundingObject USE TOKEN_GEOMETRY
  physics Physics {
    density -1
    mass 0.01
  }
  recognitionColors [
    1 1 1
  ]
}
DEF TOKEN_SILVER Solid {
  translation -1.3731863149147013e-09 0.1249960789146245 1.3000000000000023
  rotation -5.493879226546504e-09 1 1.3263426583374052e-08 0.7853996938995743
  children [
    Shape {
      appearance DEF TOKEN_APPEARANCE PBRAppearance {
        metalness 0
      }
      geometry DEF TOKEN_GEOMETRY Box {
        size 0.25 0.25 0.25
      }
    }
  ]
  name "solid(13)"
  boundingObject USE TOKEN_GEOMETRY
  physics Physics {
    density -1
    mass 0.01
  }
  recognitionColors [
    1 1 1
  ]
}
DEF TOKEN_SILVER Solid {
  translation -1.3731863149147013e-09 0.1249960789146245 -1.2999999999999978
  rotation -5.493879226546504e-09 1 1.3263426583374052e-08 0.7853996938995743
  children [
    Shape {
      appearance DEF TOKEN_APPEARANCE PBRAppearance {
        metalness 0
      }
      geometry DEF TOKEN_GEOMETRY Box {
        size 0.25 0.25 0.25
      }
    }
  ]
  name "solid(14)"
  boundingObject USE TOKEN_GEOMETRY
  physics Physics {
    density -1
    mass 0.01
  }
  recognitionColors [
    1 1 1
  ]
}
DEF TOKEN_SILVER Solid {
  translation 1.299999998626814 0.12499607891462448 2.106022558667375e-15
  rotation -5.493879200667026e-09 1 1.32634264690066e-08 0.7853996938995741
  children [
    Shape {
      appearance DEF TOKEN_APPEARANCE PBRAppearance {
        metalness 0
      }
      geometry DEF TOKEN_GEOMETRY Box {
        size 0.25 0.25 0.25
      }
    }
  ]
  name "solid(15)"
  boundingObject USE TOKEN_GEOMETRY
  physics Physics {
    density -1
    mass 0.01
  }
  recognitionColors [
    1 1 1
  ]
}
DEF TOKEN_SILVER Solid {
  translation -1.300000001373186 0.12499607891462448 2.106022558667375e-15
  rotation -5.493879200667026e-09 1 1.32634264690066e-08 0.7853996938995741
  children [
    Shape {
      appearance DEF TOKEN_APPEARANCE PBRAppearance {
        metalness 0
      }
      geometry DEF TOKEN_GEOMETRY Box {
        size 0.25 0.25 0.25
      }
    }
  ]
  name "solid(16)"
  boundingObject USE TOKEN_GEOMETRY
  physics Physics {
    density -1
    mass 0.01
  }
  recognitionColors [
    1 1 1
  ]
}
DEF Arthur Robot {
  translation 2.42027 0.185036 2.37721
  rotation -0.0060339523781327824 0.9999713941139414 -0.004560961797590053 2.38511
  children [
    Camera {
      translation 0.11 0.15 0
      rotation 0.1294279597735375 0.9831056944488314 0.1294279597735375 -1.5878253071795863
      children [
        Shape {
          appearance PBRAppearance {
            baseColor 0.46 0.1 1
            metalness 0
          }
          geometry Box {
            size 0.05 0.025 0.054
          }
        }
      ]
      fieldOfView 1
      width 800
      height 600
      recognition Recognition {
        frameThickness 3
      }
    }
    DistanceSensor {
      translation 0.125 -0.1 -0.2
      children [
        Shape {
          appearance DEF AP_DS PBRAppearance {
            baseColor 0.42 0.56 0.14
            metalness 0
          }
          geometry DEF GEO_DS Box {
            size 0.01 0.01 0.01
          }
        }
      ]
      name "DS_1"
    }
    DistanceSensor {
      translation -0.125 -0.1 0
      children [
        Shape {
          appearance DEF AP_DS PBRAppearance {
            baseColor 0.42 0.56 0.14
            metalness 0
          }
          geometry DEF GEO_DS Box {
            size 0.01 0.01 0.01
          }
        }
      ]
      name "DS_2"
    }
    DistanceSensor {
      translation 0.125 -0.1 0.2
      children [
        Shape {
          appearance DEF AP_DS PBRAppearance {
            baseColor 0.42 0.56 0.14
            metalness 0
          }
          geometry DEF GEO_DS Box {
            size 0.01 0.01 0.01
          }
        }
      ]
      name "DS_3"
    }
    DEF Wheel1 HingeJoint {
      jointParameters HingeJointParameters {
        position -57.80485289721251
        axis 0 0 1
        anchor 0.045 -0.07 0
      }
      device [
        RotationalMotor {
          name "M1"
        }
      ]
      endPoint Solid {
        translation 0.045 -0.07 -0.23999999999999438
        rotation -0.6976274717864649 0.5066152155480854 0.5066131995753682 4.359852695307466
        children [
          Shape {
            appearance DEF AP_Wheel PBRAppearance {
              baseColor 0.82 0.41 0.12
              metalness 0
            }
            geometry DEF RA_Wheel Cylinder {
              height 0.02
              radius 0.075
            }
          }
        ]
        name "solid(7)"
        boundingObject USE RA_Wheel
        physics Physics {
        }
      }
    }
    DEF Wheel2 HingeJoint {
      jointParameters HingeJointParameters {
        position -50.55048473249821
        axis 0 0 1
        anchor -0.11 -0.07 0
      }
      device [
        RotationalMotor {
          name "M3"
        }
      ]
      endPoint Solid {
        translation -0.11 -0.07 0.24000000000000737
        rotation 0.9800299461069852 -0.1406084316114652 -0.14060787208866943 1.5909710879016443
        children [
          Shape {
            appearance DEF AP_Wheel PBRAppearance {
              baseColor 0.82 0.41 0.12
              metalness 0
            }
            geometry USE RA_Wheel
          }
        ]
        name "solid(6)"
        boundingObject USE RA_Wheel
        physics Physics {
        }
      }
    }
    DEF Wheel3 HingeJoint {
      jointParameters HingeJointParameters {
        position -57.78791950583124
        axis 0 0 1
        anchor -0.11 -0.07 0
      }
      device [
        RotationalMotor {
          name "M2"
        }
      ]
      endPoint Solid {
        translation -0.11 -0.07 -0.2399999999999975
        rotation -0.7039956125756822 0.5021912905441561 0.5021892921755549 4.368394013109925
        children [
          Shape {
            appearance DEF AP_Wheel PBRAppearance {
              baseColor 0.82 0.41 0.12
              metalness 0
            }
            geometry USE RA_Wheel
          }
        ]
        name "solid(5)"
        boundingObject USE RA_Wheel
        physics Physics {
        }
      }
    }
    DEF Wheel4 HingeJoint {
      jointParameters HingeJointParameters {
        position -50.567367911856174
        axis 0 0 1
        anchor 0.045 -0.07 0
      }
      device [
        RotationalMotor {
          name "M4"
        }
      ]
      endPoint Solid {
        translation 0.045 -0.07 0.23999999999999766
        rotation 0.9776388356074884 -0.1486984920671774 -0.14869790035162395 1.593413343538228
        children [
          Shape {
            appearance DEF AP_Wheel PBRAppearance {
              baseColor 0.82 0.41 0.12
              metalness 0
            }
            geometry USE RA_Wheel
          }
        ]
        name "solid(4)"
        boundingObject USE RA_Wheel
        physics Physics {
        }
      }
    }
    DEF ROBOT_BODY Transform {
      children [
        DEF TOP Solid {
          translation -0.025 0.1675 0
          children [
            Shape {
              appearance DEF AP_BODY PBRAppearance {
                baseColor 0.3 0.3 0.3
                metalness 0
              }
              geometry DEF RA_TOP Box {
                size 0.3 0.015 0.45
              }
            }
          ]
          name "solid(3)"
          boundingObject USE RA_TOP
          physics Physics {
          }
        }
        DEF WALL_BACK Solid {
          translation -0.15 0.01 0
          children [
            Shape {
              appearance DEF AP_BODY PBRAppearance {
                baseColor 0.3 0.3 0.3
                metalness 0
              }
              geometry DEF AR_BodyBack Box {
                size 0.05 0.3 0.45
              }
            }
          ]
          name "solid(2)"
          boundingObject USE AR_BodyBack
          physics Physics {
          }
        }
        DEF WALL_LEFT Solid {
          translation 0 0.01 -0.2
          children [
            Shape {
              appearance DEF AP_BODY PBRAppearance {
                baseColor 0.3 0.3 0.3
                metalness 0
              }
              geometry DEF AR_BodyWall Box {
                size 0.25 0.3 0.05
              }
            }
          ]
          name "solid(1)"
          boundingObject USE AR_BodyWall
          physics Physics {
          }
        }
        DEF WALL_RIGHT Solid {
          translation 0 0.01 0.2
          children [
            Shape {
              appearance DEF AP_BODY PBRAppearance {
                baseColor 0.3 0.3 0.3
                metalness 0
              }
              geometry USE AR_BodyWall
            }
          ]
          boundingObject USE AR_BodyWall
          physics Physics {
          }
        }
      ]
    }
  ]
  name "Robot_Arthur"
  physics Physics {
  }
  controller "Arthur_AdvancedBoxPush"
}
